:<?xml version="1.0" ?>
<!-- =================================================================================== -->
<!-- |    This document was autogenerated by xacro from src/real_robot_description/urdf/robot.xacro | -->
<!-- |    EDITING THIS FILE BY HAND IS NOT RECOMMENDED                                 | -->
<!-- =================================================================================== -->
<robot name="robot">
  <!-- ========== link and joint ============ -->
  <!-- base-->
  <link name="base_footprint"/>
  <joint name="base_link_joint" type="fixed">
    <parent link="base_footprint"/>
    <child link="base_link"/>
  </joint>
  <link name="base_link">
    <visual>
      <origin rpy="0.0 -0.0 0.0" xyz="0 0 0"/>
      <geometry>
        <mesh filename="package://real_robot_description/meshes/visual/base.dae"/>
      </geometry>
    </visual>
    <collision>
      <origin rpy="0.0 -0.0 0.0" xyz="0 0 0"/>
      <geometry>
        <mesh filename="package://real_robot_description/meshes/collision/base.stl"/>
      </geometry>
    </collision>
    <inertial>
      <origin rpy="0 0 0" xyz="2.00996e-05 -3.688e-06 0.0177006"/>
      <mass value="0.2435530695931495"/>
      <inertia ixx="0.0005947728860841" ixy="-4.89712998e-08" ixz="-3.98940258e-08" iyy="0.0010438537280735" iyz="7.3200047e-09" izz="0.0015992215421099"/>
    </inertial>
  </link>
  <joint name="FL_coxa_link_joint" type="revolute">
    <origin rpy="0.0 -0.0 3.141592653589793" xyz="-0.0829 -0.0648 0.0413"/>
    <parent link="base_link"/>
    <child link="FL_coxa_link"/>
    <limit effort="50.0" lower="0" upper="3.14159274" velocity="10.0"/>
    <dynamics damping="0.0005" friction="0.1"/>
    <axis xyz="0.0 0.0 1.0"/>
  </joint>
  <link name="FL_coxa_link">
    <visual>
      <origin rpy="-3.138993086447196 1.5707963267948577 0.0025843521893154746" xyz="0.0445485 -1.60999e-08 -0.027225"/>
      <geometry>
        <mesh filename="package://real_robot_description/meshes/visual/coxa.dae"/>
      </geometry>
    </visual>
    <collision>
      <origin rpy="-3.138993086447196 1.5707963267948577 0.0025843521893154746" xyz="0.0445485 -1.60999e-08 -0.027225"/>
      <geometry>
        <mesh filename="package://real_robot_description/meshes/collision/coxa.stl"/>
      </geometry>
    </collision>
    <inertial>
      <origin rpy="-3.139022626852083 1.5707963267948581 0.002606695191038495" xyz="0 0 0"/>
      <mass value="0.0108197373416986"/>
      <inertia ixx="9.4679021587e-06" ixy="0.0" ixz="0.0" iyy="3.7474371854e-06" iyz="1.801230135e-07" izz="6.9009389812e-06"/>
    </inertial>
  </link>
  <joint name="FR_coxa_link_joint" type="revolute">
    <origin rpy="0.0 0.0 0.0" xyz="-0.0832 0.0646 0.0417"/>
    <parent link="base_link"/>
    <child link="FR_coxa_link"/>
    <limit effort="50.0" lower="0" upper="3.14159274" velocity="10.0"/>
    <dynamics damping="0.0005" friction="0.1"/>
    <axis xyz="0.0 0.0 1.0"/>
  </joint>
  <link name="FR_coxa_link">
    <visual>
      <origin rpy="-3.138993086447196 1.5707963267948577 0.0025843521893154746" xyz="0.0445485 -1.60999e-08 -0.027225"/>
      <geometry>
        <mesh filename="package://real_robot_description/meshes/visual/coxa.dae"/>
      </geometry>
    </visual>
    <collision>
      <origin rpy="-3.138993086447196 1.5707963267948577 0.0025843521893154746" xyz="0.0445485 -1.60999e-08 -0.027225"/>
      <geometry>
        <mesh filename="package://real_robot_description/meshes/collision/coxa.stl"/>
      </geometry>
    </collision>
    <inertial>
      <origin rpy="-3.139022626852083 1.5707963267948581 0.002606695191038495" xyz="0 0 0"/>
      <mass value="0.0108197373416986"/>
      <inertia ixx="9.4679021587e-06" ixy="0.0" ixz="0.0" iyy="3.7474371854e-06" iyz="1.801230135e-07" izz="6.9009389812e-06"/>
    </inertial>
  </link>
  <joint name="BR_coxa_link_joint" type="revolute">
    <origin rpy="0.0 0.0 0.0" xyz="0.0829 0.0646 0.0417"/>
    <parent link="base_link"/>
    <child link="BR_coxa_link"/>
    <limit effort="50.0" lower="0" upper="3.14159274" velocity="10.0"/>
    <dynamics damping="0.0005" friction="0.1"/>
    <axis xyz="0.0 0.0 1.0"/>
  </joint>
  <link name="BR_coxa_link">
    <visual>
      <origin rpy="-3.138993086447196 1.5707963267948577 0.0025843521893154746" xyz="0.0445485 -1.60999e-08 -0.027225"/>
      <geometry>
        <mesh filename="package://real_robot_description/meshes/visual/coxa.dae"/>
      </geometry>
    </visual>
    <collision>
      <origin rpy="-3.138993086447196 1.5707963267948577 0.0025843521893154746" xyz="0.0445485 -1.60999e-08 -0.027225"/>
      <geometry>
        <mesh filename="package://real_robot_description/meshes/collision/coxa.stl"/>
      </geometry>
    </collision>
    <inertial>
      <origin rpy="-3.139022626852083 1.5707963267948581 0.002606695191038495" xyz="0 0 0"/>
      <mass value="0.0108197373416986"/>
      <inertia ixx="9.4679021587e-06" ixy="0.0" ixz="0.0" iyy="3.7474371854e-06" iyz="1.801230135e-07" izz="6.9009389812e-06"/>
    </inertial>
  </link>
  <joint name="BL_coxa_link_joint" type="revolute">
    <origin rpy="0.0 0.0 3.14159274" xyz="0.0828 -0.0649 0.0417"/>
    <parent link="base_link"/>
    <child link="BL_coxa_link"/>
    <limit effort="50.0" lower="0" upper="3.14159274" velocity="10.0"/>
    <dynamics damping="0.0005" friction="0.1"/>
    <axis xyz="0.0 0.0 1.0"/>
  </joint>
  <link name="BL_coxa_link">
    <visual>
      <origin rpy="-3.138993086447196 1.5707963267948577 0.0025843521893154746" xyz="0.0445485 -1.60999e-08 -0.027225"/>
      <geometry>
        <mesh filename="package://real_robot_description/meshes/visual/coxa.dae"/>
      </geometry>
    </visual>
    <collision>
      <origin rpy="-3.138993086447196 1.5707963267948577 0.0025843521893154746" xyz="0.0445485 -1.60999e-08 -0.027225"/>
      <geometry>
        <mesh filename="package://real_robot_description/meshes/collision/coxa.stl"/>
      </geometry>
    </collision>
    <inertial>
      <origin rpy="-3.139022626852083 1.5707963267948581 0.002606695191038495" xyz="0 0 0"/>
      <mass value="0.0108197373416986"/>
      <inertia ixx="9.4679021587e-06" ixy="0.0" ixz="0.0" iyy="3.7474371854e-06" iyz="1.801230135e-07" izz="6.9009389812e-06"/>
    </inertial>
  </link>
  <joint name="FL_femur_link_joint" type="revolute">
    <origin rpy="1.57079637 -1.57079637 3.14159274" xyz="0.089097 0.027225 -0.027225"/>
    <parent link="FL_coxa_link"/>
    <child link="FL_femur_link"/>
    <limit effort="50.0" lower="0" upper="3.14159274" velocity="10.0"/>
    <dynamics damping="0.0005" friction="0.1"/>
    <axis xyz="0 0 1"/>
  </joint>
  <link name="FL_femur_link">
    <visual>
      <origin rpy="0.0 1.2246467991473532e-16 -3.141592653589793" xyz="0.0409 -1e-17 -0.0326"/>
      <geometry>
        <mesh filename="package://real_robot_description/meshes/visual/femur.dae"/>
      </geometry>
    </visual>
    <collision>
      <origin rpy="0.0 1.2246467991473532e-16 -3.141592653589793" xyz="0.0409 -1e-17 -0.0326"/>
      <geometry>
        <mesh filename="package://real_robot_description/meshes/collision/femur.stl"/>
      </geometry>
    </collision>
    <inertial>
      <origin rpy="0.0 0.0 -3.141592653589793" xyz="0.0409 -0.000614612 -0.0367939"/>
      <mass value="0.0556904648000365"/>
      <inertia ixx="1.04525687572e-05" ixy="0.0" ixz="0.0" iyy="6.63975016385e-05" iyz="-3.301023405e-07" izz="6.27040597382e-05"/>
    </inertial>
  </link>
  <joint name="FR_femur_link_joint" type="revolute">
    <origin rpy="1.57079637 -1.57079637 3.14159274" xyz="0.089097 0.027225 -0.027225"/>
    <parent link="FR_coxa_link"/>
    <child link="FR_femur_link"/>
    <limit effort="50.0" lower="0" upper="3.14159274" velocity="10.0"/>
    <dynamics damping="0.0005" friction="0.1"/>
    <axis xyz="0 0 1"/>
  </joint>
  <link name="FR_femur_link">
    <visual>
      <origin rpy="0.0 1.2246467991473532e-16 -3.141592653589793" xyz="0.0409 -1e-17 -0.0326"/>
      <geometry>
        <mesh filename="package://real_robot_description/meshes/visual/femur.dae"/>
      </geometry>
    </visual>
    <collision>
      <origin rpy="0.0 1.2246467991473532e-16 -3.141592653589793" xyz="0.0409 -1e-17 -0.0326"/>
      <geometry>
        <mesh filename="package://real_robot_description/meshes/collision/femur.stl"/>
      </geometry>
    </collision>
    <inertial>
      <origin rpy="0.0 0.0 -3.141592653589793" xyz="0.0409 -0.000614612 -0.0367939"/>
      <mass value="0.0556904648000365"/>
      <inertia ixx="1.04525687572e-05" ixy="0.0" ixz="0.0" iyy="6.63975016385e-05" iyz="-3.301023405e-07" izz="6.27040597382e-05"/>
    </inertial>
  </link>
  <joint name="BR_femur_link_joint" type="revolute">
    <origin rpy="1.57079637 -1.57079637 3.14159274" xyz="0.089097 0.027225 -0.027225"/>
    <parent link="BR_coxa_link"/>
    <child link="BR_femur_link"/>
    <limit effort="50.0" lower="0" upper="3.14159274" velocity="10.0"/>
    <dynamics damping="0.0005" friction="0.1"/>
    <axis xyz="0 0 1"/>
  </joint>
  <link name="BR_femur_link">
    <visual>
      <origin rpy="0.0 1.2246467991473532e-16 -3.141592653589793" xyz="0.0409 -1e-17 -0.0326"/>
      <geometry>
        <mesh filename="package://real_robot_description/meshes/visual/femur.dae"/>
      </geometry>
    </visual>
    <collision>
      <origin rpy="0.0 1.2246467991473532e-16 -3.141592653589793" xyz="0.0409 -1e-17 -0.0326"/>
      <geometry>
        <mesh filename="package://real_robot_description/meshes/collision/femur.stl"/>
      </geometry>
    </collision>
    <inertial>
      <origin rpy="0.0 0.0 -3.141592653589793" xyz="0.0409 -0.000614612 -0.0367939"/>
      <mass value="0.0556904648000365"/>
      <inertia ixx="1.04525687572e-05" ixy="0.0" ixz="0.0" iyy="6.63975016385e-05" iyz="-3.301023405e-07" izz="6.27040597382e-05"/>
    </inertial>
  </link>
  <joint name="BL_femur_link_joint" type="revolute">
    <origin rpy="1.57079637 -1.57079637 3.14159274" xyz="0.089097 0.027225 -0.027225"/>
    <parent link="BL_coxa_link"/>
    <child link="BL_femur_link"/>
    <limit effort="50.0" lower="0" upper="3.14159274" velocity="10.0"/>
    <dynamics damping="0.0005" friction="0.1"/>
    <axis xyz="0 0 1"/>
  </joint>
  <link name="BL_femur_link">
    <visual>
      <origin rpy="0.0 1.2246467991473532e-16 -3.141592653589793" xyz="0.0409 -1e-17 -0.0326"/>
      <geometry>
        <mesh filename="package://real_robot_description/meshes/visual/femur.dae"/>
      </geometry>
    </visual>
    <collision>
      <origin rpy="0.0 1.2246467991473532e-16 -3.141592653589793" xyz="0.0409 -1e-17 -0.0326"/>
      <geometry>
        <mesh filename="package://real_robot_description/meshes/collision/femur.stl"/>
      </geometry>
    </collision>
    <inertial>
      <origin rpy="0.0 0.0 -3.141592653589793" xyz="0.0409 -0.000614612 -0.0367939"/>
      <mass value="0.0556904648000365"/>
      <inertia ixx="1.04525687572e-05" ixy="0.0" ixz="0.0" iyy="6.63975016385e-05" iyz="-3.301023405e-07" izz="6.27040597382e-05"/>
    </inertial>
  </link>
  <joint name="FL_tibia_link_joint" type="revolute">
    <origin rpy="0 0 -1.57079637" xyz="0.0818 -7.74e-17 7.1e-18"/>
    <parent link="FL_femur_link"/>
    <child link="FL_tibia_link"/>
    <limit effort="50.0" lower="0" upper="3.14159274" velocity="10.0"/>
    <dynamics damping="0.0005" friction="0.1"/>
    <axis xyz="0 0 1"/>
  </joint>
  <link name="FL_tibia_link">
    <visual>
      <origin rpy="1.5864404220141486 -1.5707963267948541 -0.28945027597681705" xyz="0.0673955 0.15882 -0.027225"/>
      <geometry>
        <mesh filename="package://real_robot_description/meshes/visual/tibia.dae"/>
      </geometry>
    </visual>
    <collision>
      <origin rpy="1.5864404220141486 -1.5707963267948541 -0.28945027597681705" xyz="0.0673955 0.15882 -0.027225"/>
      <geometry>
        <mesh filename="package://real_robot_description/meshes/collision/tibia.stl"/>
      </geometry>
    </collision>
    <inertial>
      <origin rpy="1.5864404220141486 -1.5707963267948541 -0.28945027597681705" xyz="0.0366413 0.0594266 -0.0275903"/>
      <mass value="0.0270130264684768"/>
      <inertia ixx="6.93465993198e-05" ixy="1.337658191e-07" ixz="6.102521657e-07" iyy="7.87462488973e-05" iyz="-3.9937390341e-06" izz="1.3325052442e-05"/>
    </inertial>
  </link>
  <joint name="FR_tibia_link_joint" type="revolute">
    <origin rpy="0 0 -1.57079637" xyz="0.0818 -7.74e-17 7.1e-18"/>
    <parent link="FR_femur_link"/>
    <child link="FR_tibia_link"/>
    <limit effort="50.0" lower="0" upper="3.14159274" velocity="10.0"/>
    <dynamics damping="0.0005" friction="0.1"/>
    <axis xyz="0 0 1"/>
  </joint>
  <link name="FR_tibia_link">
    <visual>
      <origin rpy="1.5864404220141486 -1.5707963267948541 -0.28945027597681705" xyz="0.0673955 0.15882 -0.027225"/>
      <geometry>
        <mesh filename="package://real_robot_description/meshes/visual/tibia.dae"/>
      </geometry>
    </visual>
    <collision>
      <origin rpy="1.5864404220141486 -1.5707963267948541 -0.28945027597681705" xyz="0.0673955 0.15882 -0.027225"/>
      <geometry>
        <mesh filename="package://real_robot_description/meshes/collision/tibia.stl"/>
      </geometry>
    </collision>
    <inertial>
      <origin rpy="1.5864404220141486 -1.5707963267948541 -0.28945027597681705" xyz="0.0366413 0.0594266 -0.0275903"/>
      <mass value="0.0270130264684768"/>
      <inertia ixx="6.93465993198e-05" ixy="1.337658191e-07" ixz="6.102521657e-07" iyy="7.87462488973e-05" iyz="-3.9937390341e-06" izz="1.3325052442e-05"/>
    </inertial>
  </link>
  <joint name="BR_tibia_link_joint" type="revolute">
    <origin rpy="0 0 -1.57079637" xyz="0.0818 -7.74e-17 7.1e-18"/>
    <parent link="BR_femur_link"/>
    <child link="BR_tibia_link"/>
    <limit effort="50.0" lower="0" upper="3.14159274" velocity="10.0"/>
    <dynamics damping="0.0005" friction="0.1"/>
    <axis xyz="0 0 1"/>
  </joint>
  <link name="BR_tibia_link">
    <visual>
      <origin rpy="1.5864404220141486 -1.5707963267948541 -0.28945027597681705" xyz="0.0673955 0.15882 -0.027225"/>
      <geometry>
        <mesh filename="package://real_robot_description/meshes/visual/tibia.dae"/>
      </geometry>
    </visual>
    <collision>
      <origin rpy="1.5864404220141486 -1.5707963267948541 -0.28945027597681705" xyz="0.0673955 0.15882 -0.027225"/>
      <geometry>
        <mesh filename="package://real_robot_description/meshes/collision/tibia.stl"/>
      </geometry>
    </collision>
    <inertial>
      <origin rpy="1.5864404220141486 -1.5707963267948541 -0.28945027597681705" xyz="0.0366413 0.0594266 -0.0275903"/>
      <mass value="0.0270130264684768"/>
      <inertia ixx="6.93465993198e-05" ixy="1.337658191e-07" ixz="6.102521657e-07" iyy="7.87462488973e-05" iyz="-3.9937390341e-06" izz="1.3325052442e-05"/>
    </inertial>
  </link>
  <joint name="BL_tibia_link_joint" type="revolute">
    <origin rpy="0 0 -1.57079637" xyz="0.0818 -7.74e-17 7.1e-18"/>
    <parent link="BL_femur_link"/>
    <child link="BL_tibia_link"/>
    <limit effort="50.0" lower="0" upper="3.14159274" velocity="10.0"/>
    <dynamics damping="0.0005" friction="0.1"/>
    <axis xyz="0 0 1"/>
  </joint>
  <link name="BL_tibia_link">
    <visual>
      <origin rpy="1.5864404220141486 -1.5707963267948541 -0.28945027597681705" xyz="0.0673955 0.15882 -0.027225"/>
      <geometry>
        <mesh filename="package://real_robot_description/meshes/visual/tibia.dae"/>
      </geometry>
    </visual>
    <collision>
      <origin rpy="1.5864404220141486 -1.5707963267948541 -0.28945027597681705" xyz="0.0673955 0.15882 -0.027225"/>
      <geometry>
        <mesh filename="package://real_robot_description/meshes/collision/tibia.stl"/>
      </geometry>
    </collision>
    <inertial>
      <origin rpy="1.5864404220141486 -1.5707963267948541 -0.28945027597681705" xyz="0.0366413 0.0594266 -0.0275903"/>
      <mass value="0.0270130264684768"/>
      <inertia ixx="6.93465993198e-05" ixy="1.337658191e-07" ixz="6.102521657e-07" iyy="7.87462488973e-05" iyz="-3.9937390341e-06" izz="1.3325052442e-05"/>
    </inertial>
  </link>
  <joint name="imu_joint" type="fixed">
    <origin rpy="0 0 0" xyz="0 0 0"/>
    <parent link="base_link"/>
    <child link="imu_link"/>
  </joint>
  <link name="imu_link">
    <!--
	  <visual>
		<geometry>
		  <mesh filename="package://omni_robot_description/meshes/DAE/IMU/IMU_sensor.dae"/>
		</geometry>
	  </visual>
	  -->
    <inertial>
      <origin xyz="0 0 0"/>
      <mass value="0.005"/>
      <inertia ixx="1.67e-8" ixy="0" ixz="0" iyy="1.67e-8" iyz="0" izz="1.67e-8"/>
    </inertial>
  </link>
  <ros2_control name="krsri" type="system">
    <hardware>
      <plugin>krsri_robot_hardware/RobotSystem</plugin>
    </hardware>
    <joint name="FL_coxa_link_joint">
      <command_interface name="position"/>
      <state_interface name="position"/>
    </joint>
    <joint name="FR_coxa_link_joint">
      <command_interface name="position"/>
      <state_interface name="position"/>
    </joint>
    <joint name="BR_coxa_link_joint">
      <command_interface name="position"/>
      <state_interface name="position"/>
    </joint>
    <joint name="BL_coxa_link_joint">
      <command_interface name="position"/>
      <state_interface name="position"/>
    </joint>
    <joint name="FL_femur_link_joint">
      <command_interface name="position"/>
      <state_interface name="position"/>
    </joint>
    <joint name="FR_femur_link_joint">
      <command_interface name="position"/>
      <state_interface name="position"/>
    </joint>
    <joint name="BR_femur_link_joint">
      <command_interface name="position"/>
      <state_interface name="position"/>
    </joint>
    <joint name="BL_femur_link_joint">
      <command_interface name="position"/>
      <state_interface name="position"/>
    </joint>
    <joint name="FL_tibia_link_joint">
      <command_interface name="position"/>
      <state_interface name="position"/>
    </joint>
    <joint name="FR_tibia_link_joint">
      <command_interface name="position"/>
      <state_interface name="position"/>
    </joint>
    <joint name="BR_tibia_link_joint">
      <command_interface name="position"/>
      <state_interface name="position"/>
    </joint>
    <joint name="BL_tibia_link_joint">
      <command_interface name="position"/>
      <state_interface name="position"/>
    </joint>
  </ros2_control>
  <!-- ====================== GAZEBO ================== -->
  <gazebo>
    <plugin filename="libgazebo_ros_control.so" name="gazebo_ros_control"/>
    <!-- base link odometry-->
    <plugin>
      <alwaysOn>true</alwaysOn>
      <updateRate>50</updateRate>
      <bodyName>base_link</bodyName>
      <topicName>krsri/odom</topicName>
      <gaussianNoise>0.01</gaussianNoise>
      <frameName>world</frameName>
      <xyzOffsets>0 0 0 </xyzOffsets>
      <rpyOffsets>0 0 0</rpyOffsets>
    </plugin>
  </gazebo>
  <transmission name="FL_coxa_link_trans_v0">
    <type>transmission_interface/SimpleTransmission</type>
    <joint name="FL_coxa_link_joint">
      <hardwareInterface>hardware_interface/PositionJointInterface</hardwareInterface>
    </joint>
    <actuator name="FL_coxa_link_joint_motor">
      <hardwareInterface>hardware_interface/PositionJointInterface</hardwareInterface>
      <mechanicalReduction>1</mechanicalReduction>
    </actuator>
  </transmission>
  <transmission name="FR_coxa_link_trans_v0">
    <type>transmission_interface/SimpleTransmission</type>
    <joint name="FR_coxa_link_joint">
      <hardwareInterface>hardware_interface/PositionJointInterface</hardwareInterface>
    </joint>
    <actuator name="FR_coxa_link_joint_motor">
      <hardwareInterface>hardware_interface/PositionJointInterface</hardwareInterface>
      <mechanicalReduction>1</mechanicalReduction>
    </actuator>
  </transmission>
  <transmission name="BR_coxa_link_trans_v0">
    <type>transmission_interface/SimpleTransmission</type>
    <joint name="BR_coxa_link_joint">
      <hardwareInterface>hardware_interface/PositionJointInterface</hardwareInterface>
    </joint>
    <actuator name="BR_coxa_link_joint_motor">
      <hardwareInterface>hardware_interface/PositionJointInterface</hardwareInterface>
      <mechanicalReduction>1</mechanicalReduction>
    </actuator>
  </transmission>
  <transmission name="BL_coxa_link_trans_v0">
    <type>transmission_interface/SimpleTransmission</type>
    <joint name="BL_coxa_link_joint">
      <hardwareInterface>hardware_interface/PositionJointInterface</hardwareInterface>
    </joint>
    <actuator name="BL_coxa_link_joint_motor">
      <hardwareInterface>hardware_interface/PositionJointInterface</hardwareInterface>
      <mechanicalReduction>1</mechanicalReduction>
    </actuator>
  </transmission>
  <transmission name="FL_femur_link_trans_v0">
    <type>transmission_interface/SimpleTransmission</type>
    <joint name="FL_femur_link_joint">
      <hardwareInterface>hardware_interface/PositionJointInterface</hardwareInterface>
    </joint>
    <actuator name="FL_femur_link_joint_motor">
      <hardwareInterface>hardware_interface/PositionJointInterface</hardwareInterface>
      <mechanicalReduction>1</mechanicalReduction>
    </actuator>
  </transmission>
  <transmission name="FR_femur_link_trans_v0">
    <type>transmission_interface/SimpleTransmission</type>
    <joint name="FR_femur_link_joint">
      <hardwareInterface>hardware_interface/PositionJointInterface</hardwareInterface>
    </joint>
    <actuator name="FR_femur_link_joint_motor">
      <hardwareInterface>hardware_interface/PositionJointInterface</hardwareInterface>
      <mechanicalReduction>1</mechanicalReduction>
    </actuator>
  </transmission>
  <transmission name="BR_femur_link_trans_v0">
    <type>transmission_interface/SimpleTransmission</type>
    <joint name="BR_femur_link_joint">
      <hardwareInterface>hardware_interface/PositionJointInterface</hardwareInterface>
    </joint>
    <actuator name="BR_femur_link_joint_motor">
      <hardwareInterface>hardware_interface/PositionJointInterface</hardwareInterface>
      <mechanicalReduction>1</mechanicalReduction>
    </actuator>
  </transmission>
  <transmission name="BL_femur_link_trans_v0">
    <type>transmission_interface/SimpleTransmission</type>
    <joint name="BL_femur_link_joint">
      <hardwareInterface>hardware_interface/PositionJointInterface</hardwareInterface>
    </joint>
    <actuator name="BL_femur_link_joint_motor">
      <hardwareInterface>hardware_interface/PositionJointInterface</hardwareInterface>
      <mechanicalReduction>1</mechanicalReduction>
    </actuator>
  </transmission>
  <transmission name="FL_tibia_link_trans_v0">
    <type>transmission_interface/SimpleTransmission</type>
    <joint name="FL_tibia_link_joint">
      <hardwareInterface>hardware_interface/PositionJointInterface</hardwareInterface>
    </joint>
    <actuator name="FL_tibia_link_joint_motor">
      <hardwareInterface>hardware_interface/PositionJointInterface</hardwareInterface>
      <mechanicalReduction>1</mechanicalReduction>
    </actuator>
  </transmission>
  <transmission name="FR_tibia_link_trans_v0">
    <type>transmission_interface/SimpleTransmission</type>
    <joint name="FR_tibia_link_joint">
      <hardwareInterface>hardware_interface/PositionJointInterface</hardwareInterface>
    </joint>
    <actuator name="FR_tibia_link_joint_motor">
      <hardwareInterface>hardware_interface/PositionJointInterface</hardwareInterface>
      <mechanicalReduction>1</mechanicalReduction>
    </actuator>
  </transmission>
  <transmission name="BR_tibia_link_trans_v0">
    <type>transmission_interface/SimpleTransmission</type>
    <joint name="BR_tibia_link_joint">
      <hardwareInterface>hardware_interface/PositionJointInterface</hardwareInterface>
    </joint>
    <actuator name="BR_tibia_link_joint_motor">
      <hardwareInterface>hardware_interface/PositionJointInterface</hardwareInterface>
      <mechanicalReduction>1</mechanicalReduction>
    </actuator>
  </transmission>
  <transmission name="BL_tibia_link_trans_v0">
    <type>transmission_interface/SimpleTransmission</type>
    <joint name="BL_tibia_link_joint">
      <hardwareInterface>hardware_interface/PositionJointInterface</hardwareInterface>
    </joint>
    <actuator name="BL_tibia_link_joint_motor">
      <hardwareInterface>hardware_interface/PositionJointInterface</hardwareInterface>
      <mechanicalReduction>1</mechanicalReduction>
    </actuator>
  </transmission>
  <gazebo reference="base_link">
    <selfCollide>false</selfCollide>
    <mu1 value="0.05"/>
    <mu2 value="0.05"/>
  </gazebo>
  <gazebo reference="FL_coxa_link_link">
    <selfCollide>false</selfCollide>
    <mu1>1.0</mu1>
    <mu2>1.0</mu2>
    <minDepth>0.0002</minDepth>
    <kp value="1000000.0"/>
    <kd value="100.0"/>
  </gazebo>
  <gazebo reference="FR_coxa_link_link">
    <selfCollide>false</selfCollide>
    <mu1>1.0</mu1>
    <mu2>1.0</mu2>
    <minDepth>0.0002</minDepth>
    <kp value="1000000.0"/>
    <kd value="100.0"/>
  </gazebo>
  <gazebo reference="BR_coxa_link_link">
    <selfCollide>false</selfCollide>
    <mu1>1.0</mu1>
    <mu2>1.0</mu2>
    <minDepth>0.0002</minDepth>
    <kp value="1000000.0"/>
    <kd value="100.0"/>
  </gazebo>
  <gazebo reference="BL_coxa_link_link">
    <selfCollide>false</selfCollide>
    <mu1>1.0</mu1>
    <mu2>1.0</mu2>
    <minDepth>0.0002</minDepth>
    <kp value="1000000.0"/>
    <kd value="100.0"/>
  </gazebo>
  <gazebo reference="FL_femur_link_link">
    <selfCollide>false</selfCollide>
    <mu1>1.0</mu1>
    <mu2>1.0</mu2>
    <minDepth>0.0002</minDepth>
    <kp value="1000000.0"/>
    <kd value="100.0"/>
  </gazebo>
  <gazebo reference="FR_femur_link_link">
    <selfCollide>false</selfCollide>
    <mu1>1.0</mu1>
    <mu2>1.0</mu2>
    <minDepth>0.0002</minDepth>
    <kp value="1000000.0"/>
    <kd value="100.0"/>
  </gazebo>
  <gazebo reference="BR_femur_link_link">
    <selfCollide>false</selfCollide>
    <mu1>1.0</mu1>
    <mu2>1.0</mu2>
    <minDepth>0.0002</minDepth>
    <kp value="1000000.0"/>
    <kd value="100.0"/>
  </gazebo>
  <gazebo reference="BL_femur_link_link">
    <selfCollide>false</selfCollide>
    <mu1>1.0</mu1>
    <mu2>1.0</mu2>
    <minDepth>0.0002</minDepth>
    <kp value="1000000.0"/>
    <kd value="100.0"/>
  </gazebo>
  <gazebo reference="FL_tibia_link_link">
    <selfCollide>false</selfCollide>
    <mu1>1.0</mu1>
    <mu2>1.0</mu2>
    <minDepth>0.0002</minDepth>
    <kp value="1000000.0"/>
    <kd value="100.0"/>
  </gazebo>
  <gazebo reference="FR_tibia_link_link">
    <selfCollide>false</selfCollide>
    <mu1>1.0</mu1>
    <mu2>1.0</mu2>
    <minDepth>0.0002</minDepth>
    <kp value="1000000.0"/>
    <kd value="100.0"/>
  </gazebo>
  <gazebo reference="BR_tibia_link_link">
    <selfCollide>false</selfCollide>
    <mu1>1.0</mu1>
    <mu2>1.0</mu2>
    <minDepth>0.0002</minDepth>
    <kp value="1000000.0"/>
    <kd value="100.0"/>
  </gazebo>
  <gazebo reference="BL_tibia_link_link">
    <selfCollide>false</selfCollide>
    <mu1>1.0</mu1>
    <mu2>1.0</mu2>
    <minDepth>0.0002</minDepth>
    <kp value="1000000.0"/>
    <kd value="100.0"/>
  </gazebo>
  <gazebo reference="imu_link">
    <gravity>true</gravity>
    <sensor name="imu_sensor" type="imu">
      <always_on>true</always_on>
      <update_rate>100</update_rate>
      <visualize>true</visualize>
      <topic>__default_topic__</topic>
      <pose>0 0 0 0 0 0</pose>
      <plugin filename="libgazebo_ros_imu_sensor.so" name="imu_plugin">
        <topicName>a1_imu/base_link_orientation</topicName>
        <update_rate>0</update_rate>
        <bodyName>imu_link</bodyName>
        <updateRateHZ>15.0</updateRateHZ>
        <gaussianNoise>0.0</gaussianNoise>
        <xyzOffset>0 0 0</xyzOffset>
        <rpyOffset>0 0 0</rpyOffset>
        <frameName>base_link</frameName>
        <initialOrientationAsReference>false</initialOrientationAsReference>
      </plugin>
    </sensor>
  </gazebo>
</robot>
